Workbook

Sheet 说明
A1: FemTech 与生殖健康：跨国分析数据底稿（附件二）
A2: 两条证据链并列呈现：跨国模型检验政治体制类型与生殖健康结果的生态关联；隐私证据独立综述应用审计与执法案例。两者不合并，也不在国家层面相互连接。
A4: 项目 | B4: 说明
A5: 论文定位 | B5: 跨国部分仅检验政治体制类型与生殖健康结果的生态关联；隐私部分独立综述应用审计与执法证据。
A6: 分析总体 | B6: 167国分析总体。2023年OWID存档政治体制序列无统一PSE观测值，因此含政治体制的模型 n=166，CPR 模型 n=138。
A7: 主要规格 | B7: log(MMR) ~ 政治体制有序趋势 + logGDP；CPR ~ 政治体制有序趋势 + logGDP。HC3为主要推断，经典OLS并列。
A8: 有序假设 | B8: 政治体制0/1/2/3被视为等距线性趋势；三个虚拟变量模型作为放松等距假设的敏感性分析。
A9: CPR规则 | B9: 主样本采用2010–2023年最新非缺失值并逐国保留年份；另做2015–2023限制样本与加入观测年份的敏感性分析。
A10: 缺失风险 | B10: CPR缺失可能非随机，且在自由民主组集中。HC3只处理异方差，不处理选择性缺失。
A11: 数据与版本 | B11: 政治体制锁定OWID 2026-08-05官方存档（V-Dem v16）；WDI JSON快照保留SHA-256。
A12: 推论边界 | B12: 本工作簿中的国别模型只描述政治体制类型与生殖健康结果之间的生态关联。模型未检验隐私法效应，也未建立 FemTech 采用或隐私事件与政治体制之间的国家层面联系。

Sheet 数据源
A1: 数据源登记表
A2: 完整URL、版本、日期、口径、原始文件名与SHA-256均为可追溯的审计字段。
A4: 数据集 | B4: 来源机构 | C4: 版本/存档 | D4: 下载日期 | E4: 完整URL | F4: 查询范围 | G4: 单位 | H4: 观测年份规则 | I4: 原始文件名 | J4: SHA-256
A5: Maternal mortality ratio | B5: World Bank, World Development Indicators | C5: API snapshot; last updated 2026-07-13 | D5: 2026-09-03 | E5: https://api.worldbank.org/v2/country/all/indicator/SH.STA.MMRT?format=json&per_page=20000 | F5: All economies; latest non-missing observation in 2010-2023 for the retained 167-country analytic sample | G5: Maternal deaths per 100,000 live births | H5: Latest non-missing value, 2010-2023 | I5: mmr.json | J5: d19e18021c680f5f910b13c9d9f93d4219824cc5b0f44350e1b69e8840b07c73
A6: GDP per capita, PPP | B6: World Bank, World Development Indicators | C6: API snapshot; last updated 2026-07-13 | D6: 2026-09-03 | E6: https://api.worldbank.org/v2/country/all/indicator/NY.GDP.PCAP.PP.KD?format=json&per_page=20000 | F6: All economies; latest non-missing observation in 2010-2023 for the retained 167-country analytic sample | G6: Constant 2021 international dollars per person | H6: Latest non-missing value, 2010-2023; log generated as LN(raw GDP) | I6: gdp.json | J6: c610e48829239b4b7fbdae26883093fa70f0c2e4cff6845d314beec722c7f6a5
A7: Contraceptive prevalence, any method | B7: World Bank, World Development Indicators | C7: API snapshot; last updated 2026-07-13 | D7: 2026-09-03 | E7: https://api.worldbank.org/v2/country/all/indicator/SP.DYN.CONU.ZS?format=json&per_page=20000 | F7: All economies; latest non-missing observation in 2010-2023 for the retained 167-country analytic sample | G7: % of married women ages 15-49 | H7: Latest non-missing value, 2010-2023; missing retained and flagged | I7: cpr.json | J7: 260237f909d0f09b84eae91b3746403ffaec82199b23c02a0669e9ff28cc76e5
A8: Political regime (Regimes of the World) | B8: V-Dem v16, processed by Our World in Data | C8: OWID archive 2026-08-05 14:35 UTC; source last updated 2026-03-17 | D8: 2026-09-03 | E8: https://archive.ourworldindata.org/20260805-143540/grapher/political-regime.html | F8: 2023 classification for the retained 167-country analytic sample | G8: 0 closed autocracy; 1 electoral autocracy; 2 electoral democracy; 3 liberal democracy | H8: Fixed at 2023 | I8: 1210053.data.json + 1210053.metadata.json | J8: 03b99952aae74eb78cdfaf600be6178eff422356e412447ad43d7f103e5bf1fd / 5b86ddda5ba7f246d1983e12e37e8628258d46eae179e88beed0d9cad822c24d
A10: 注：表中 SHA-256 为按上述 URL 于「下载日期」抓取的原始文件（WDI 三个 JSON 与 OWID 政治体制数据文件）校验值。重新抓取时若源端已更新，校验值可能不同；验证需使用同日抓取的原始文件。

Sheet 跨国底稿
A1: 跨国逐国审计底稿
A2: 每行一国；黄色列为公式生成。PSE保留在167国审计总体中，但2023年无统一政治体制观测。
A4: ISO3 | B4: 国家 | C4: MMR | D4: MMR年份 | E4: 原始GDP | F4: GDP年份 | G4: logGDP（公式） | H4: 政治体制代码 | I4: 文字类别 | J4: 政治体制年份 | K4: CPR | L4: CPR年份 | M4: CPR缺失标记（公式） | N4: log(MMR)（公式） | O4: Regime=1 | P4: Regime=2 | Q4: Regime=3 | R4: CPR年份-2018 | S4: 审计备注
A5: AFG | B5: Afghanistan | C5: 521 | D5: 2023 | E5: 1983.8126 | F5: 2023 | G5: =LN(E5) -> 7.5927758 | H5: 0 | I5: Closed autocracy | J5: 2023 | K5: 22.5 | L5: 2015 | M5: =IF(K5="","Missing","Observed") -> Observed | N5: =LN(C5) -> 6.25575 | O5: =IF($H5=1,1,0) -> 0 | P5: =IF($H5=2,1,0) -> 0 | Q5: =IF($H5=3,1,0) -> 0 | R5: =IF($L5="","",$L5-2018) -> -3
A6: ALB | B6: Albania | C6: 7 | D6: 2023 | E6: 20501.647 | F6: 2023 | G6: =LN(E6) -> 9.9282605 | H6: 2 | I6: Electoral democracy | J6: 2023 | K6: 46 | L6: 2018 | M6: =IF(K6="","Missing","Observed") -> Observed | N6: =LN(C6) -> 1.9459101 | O6: =IF($H6=1,1,0) -> 0 | P6: =IF($H6=2,1,0) -> 1 | Q6: =IF($H6=3,1,0) -> 0 | R6: =IF($L6="","",$L6-2018) -> 0
A7: DZA | B7: Algeria | C7: 62 | D7: 2023 | E7: 15159.324 | F7: 2023 | G7: =LN(E7) -> 9.6263711 | H7: 1 | I7: Electoral autocracy | J7: 2023 | K7: 53.6 | L7: 2019 | M7: =IF(K7="","Missing","Observed") -> Observed | N7: =LN(C7) -> 4.1271344 | O7: =IF($H7=1,1,0) -> 1 | P7: =IF($H7=2,1,0) -> 0 | Q7: =IF($H7=3,1,0) -> 0 | R7: =IF($L7="","",$L7-2018) -> 1
A8: AGO | B8: Angola | C8: 183 | D8: 2023 | E8: 8597.5388 | F8: 2023 | G8: =LN(E8) -> 9.0592313 | H8: 1 | I8: Electoral autocracy | J8: 2023 | K8: 13.7 | L8: 2016 | M8: =IF(K8="","Missing","Observed") -> Observed | N8: =LN(C8) -> 5.2094862 | O8: =IF($H8=1,1,0) -> 1 | P8: =IF($H8=2,1,0) -> 0 | Q8: =IF($H8=3,1,0) -> 0 | R8: =IF($L8="","",$L8-2018) -> -2
A9: ARG | B9: Argentina | C9: 33 | D9: 2023 | E9: 27230.397 | F9: 2023 | G9: =LN(E9) -> 10.212089 | H9: 2 | I9: Electoral democracy | J9: 2023 | K9: 70.102709 | L9: 2020 | M9: =IF(K9="","Missing","Observed") -> Observed | N9: =LN(C9) -> 3.4965076 | O9: =IF($H9=1,1,0) -> 0 | P9: =IF($H9=2,1,0) -> 1 | Q9: =IF($H9=3,1,0) -> 0 | R9: =IF($L9="","",$L9-2018) -> 2
A10: ARM | B10: Armenia | C10: 19 | D10: 2023 | E10: 19402.751 | F10: 2023 | G10: =LN(E10) -> 9.8731701 | H10: 2 | I10: Electoral democracy | J10: 2023 | K10: 57.1 | L10: 2016 | M10: =IF(K10="","Missing","Observed") -> Observed | N10: =LN(C10) -> 2.944439 | O10: =IF($H10=1,1,0) -> 0 | P10: =IF($H10=2,1,0) -> 1 | Q10: =IF($H10=3,1,0) -> 0 | R10: =IF($L10="","",$L10-2018) -> -2
A11: AUS | B11: Australia | C11: 2 | D11: 2023 | E11: 60684.96 | F11: 2023 | G11: =LN(E11) -> 11.013451 | H11: 3 | I11: Liberal democracy | J11: 2023 | K11: 66.93 | L11: 2016 | M11: =IF(K11="","Missing","Observed") -> Observed | N11: =LN(C11) -> 0.69314718 | O11: =IF($H11=1,1,0) -> 0 | P11: =IF($H11=2,1,0) -> 0 | Q11: =IF($H11=3,1,0) -> 1 | R11: =IF($L11="","",$L11-2018) -> -2
A12: AUT | B12: Austria | C12: 6 | D12: 2023 | E12: 64536.208 | F12: 2023 | G12: =LN(E12) -> 11.074982 | H12: 3 | I12: Liberal democracy | J12: 2023 | K12: 65.652575 | L12: 2013 | M12: =IF(K12="","Missing","Observed") -> Observed | N12: =LN(C12) -> 1.7917595 | O12: =IF($H12=1,1,0) -> 0 | P12: =IF($H12=2,1,0) -> 0 | Q12: =IF($H12=3,1,0) -> 1 | R12: =IF($L12="","",$L12-2018) -> -5
A13: AZE | B13: Azerbaijan | C13: 18 | D13: 2023 | E13: 21310.739 | F13: 2023 | G13: =LN(E13) -> 9.9669664 | H13: 1 | I13: Electoral autocracy | J13: 2023 | K13: 54.9 | L13: 2011 | M13: =IF(K13="","Missing","Observed") -> Observed | N13: =LN(C13) -> 2.8903718 | O13: =IF($H13=1,1,0) -> 1 | P13: =IF($H13=2,1,0) -> 0 | Q13: =IF($H13=3,1,0) -> 0 | R13: =IF($L13="","",$L13-2018) -> -7
A14: BHR | B14: Bahrain | C14: 17 | D14: 2023 | E14: 57819.905 | F14: 2023 | G14: =LN(E14) -> 10.965088 | H14: 0 | I14: Closed autocracy | J14: 2023 | M14: =IF(K14="","Missing","Observed") -> Missing | N14: =LN(C14) -> 2.8332133 | O14: =IF($H14=1,1,0) -> 0 | P14: =IF($H14=2,1,0) -> 0 | Q14: =IF($H14=3,1,0) -> 0 | R14: =IF($L14="","",$L14-2018)
A15: BGD | B15: Bangladesh | C15: 115 | D15: 2023 | E15: 8242.398 | F15: 2023 | G15: =LN(E15) -> 9.0170466 | H15: 1 | I15: Electoral autocracy | J15: 2023 | K15: 64 | L15: 2022 | M15: =IF(K15="","Missing","Observed") -> Observed | N15: =LN(C15) -> 4.7449321 | O15: =IF($H15=1,1,0) -> 1 | P15: =IF($H15=2,1,0) -> 0 | Q15: =IF($H15=3,1,0) -> 0 | R15: =IF($L15="","",$L15-2018) -> 4
A16: BRB | B16: Barbados | C16: 35 | D16: 2023 | E16: 20865.016 | F16: 2023 | G16: =LN(E16) -> 9.9458291 | H16: 3 | I16: Liberal democracy | J16: 2023 | K16: 59.20685 | L16: 2012 | M16: =IF(K16="","Missing","Observed") -> Observed | N16: =LN(C16) -> 3.5553481 | O16: =IF($H16=1,1,0) -> 0 | P16: =IF($H16=2,1,0) -> 0 | Q16: =IF($H16=3,1,0) -> 1 | R16: =IF($L16="","",$L16-2018) -> -6
A17: BLR | B17: Belarus | C17: 1 | D17: 2023 | E17: 27782.438 | F17: 2023 | G17: =LN(E17) -> 10.232159 | H17: 1 | I17: Electoral autocracy | J17: 2023 | K17: 52.6 | L17: 2019 | M17: =IF(K17="","Missing","Observed") -> Observed | N17: =LN(C17) -> 0 | O17: =IF($H17=1,1,0) -> 1 | P17: =IF($H17=2,1,0) -> 0 | Q17: =IF($H17=3,1,0) -> 0 | R17: =IF($L17="","",$L17-2018) -> 1
A18: BEL | B18: Belgium | C18: 4 | D18: 2023 | E18: 63042.01 | F18: 2023 | G18: =LN(E18) -> 11.051557 | H18: 3 | I18: Liberal democracy | J18: 2023 | K18: 66.7 | L18: 2018 | M18: =IF(K18="","Missing","Observed") -> Observed | N18: =LN(C18) -> 1.3862944 | O18: =IF($H18=1,1,0) -> 0 | P18: =IF($H18=2,1,0) -> 0 | Q18: =IF($H18=3,1,0) -> 1 | R18: =IF($L18="","",$L18-2018) -> 0
A19: BEN | B19: Benin | C19: 518 | D19: 2023 | E19: 3721.2125 | F19: 2023 | G19: =LN(E19) -> 8.2218048 | H19: 1 | I19: Electoral autocracy | J19: 2023 | K19: 22.4 | L19: 2022 | M19: =IF(K19="","Missing","Observed") -> Observed | N19: =LN(C19) -> 6.2499752 | O19: =IF($H19=1,1,0) -> 1 | P19: =IF($H19=2,1,0) -> 0 | Q19: =IF($H19=3,1,0) -> 0 | R19: =IF($L19="","",$L19-2018) -> 4
A20: BTN | B20: Bhutan | C20: 47 | D20: 2023 | E20: 14610.296 | F20: 2023 | G20: =LN(E20) -> 9.5894818 | H20: 3 | I20: Liberal democracy | J20: 2023 | K20: 65.604097 | L20: 2010 | M20: =IF(K20="","Missing","Observed") -> Observed | N20: =LN(C20) -> 3.8501476 | O20: =IF($H20=1,1,0) -> 0 | P20: =IF($H20=2,1,0) -> 0 | Q20: =IF($H20=3,1,0) -> 1 | R20: =IF($L20="","",$L20-2018) -> -8
A21: BOL | B21: Bolivia | C21: 146 | D21: 2023 | E21: 11616.158 | F21: 2023 | G21: =LN(E21) -> 9.3601523 | H21: 2 | I21: Electoral democracy | J21: 2023 | K21: 66.5 | L21: 2016 | M21: =IF(K21="","Missing","Observed") -> Observed | N21: =LN(C21) -> 4.9836066 | O21: =IF($H21=1,1,0) -> 0 | P21: =IF($H21=2,1,0) -> 1 | Q21: =IF($H21=3,1,0) -> 0 | R21: =IF($L21="","",$L21-2018) -> -2
A22: BIH | B22: Bosnia and Herzegovina | C22: 6 | D22: 2023 | E22: 19804.918 | F22: 2023 | G22: =LN(E22) -> 9.8936856 | H22: 2 | I22: Electoral democracy | J22: 2023 | K22: 46.01743 | L22: 2012 | M22: =IF(K22="","Missing","Observed") -> Observed | N22: =LN(C22) -> 1.7917595 | O22: =IF($H22=1,1,0) -> 0 | P22: =IF($H22=2,1,0) -> 1 | Q22: =IF($H22=3,1,0) -> 0 | R22: =IF($L22="","",$L22-2018) -> -6
A23: BWA | B23: Botswana | C23: 155 | D23: 2023 | E23: 18932.48 | F23: 2023 | G23: =LN(E23) -> 9.8486343 | H23: 2 | I23: Electoral democracy | J23: 2023 | K23: 67.4 | L23: 2017 | M23: =IF(K23="","Missing","Observed") -> Observed | N23: =LN(C23) -> 5.0434251 | O23: =IF($H23=1,1,0) -> 0 | P23: =IF($H23=2,1,0) -> 1 | Q23: =IF($H23=3,1,0) -> 0 | R23: =IF($L23="","",$L23-2018) -> -1
A24: BRA | B24: Brazil | C24: 67 | D24: 2023 | E24: 19079.812 | F24: 2023 | G24: =LN(E24) -> 9.8563861 | H24: 2 | I24: Electoral democracy | J24: 2023 | K24: 80.2005 | L24: 2013 | M24: =IF(K24="","Missing","Observed") -> Observed | N24: =LN(C24) -> 4.2046926 | O24: =IF($H24=1,1,0) -> 0 | P24: =IF($H24=2,1,0) -> 1 | Q24: =IF($H24=3,1,0) -> 0 | R24: =IF($L24="","",$L24-2018) -> -5
A25: BGR | B25: Bulgaria | C25: 6 | D25: 2023 | E25: 33073.68 | F25: 2023 | G25: =LN(E25) -> 10.406493 | H25: 2 | I25: Electoral democracy | J25: 2023 | M25: =IF(K25="","Missing","Observed") -> Missing | N25: =LN(C25) -> 1.7917595 | O25: =IF($H25=1,1,0) -> 0 | P25: =IF($H25=2,1,0) -> 1 | Q25: =IF($H25=3,1,0) -> 0 | R25: =IF($L25="","",$L25-2018)
A26: BFA | B26: Burkina Faso | C26: 242 | D26: 2023 | E26: 2486.2067 | F26: 2023 | G26: =LN(E26) -> 7.8185134 | H26: 0 | I26: Closed autocracy | J26: 2023 | K26: 33.96274 | L26: 2022 | M26: =IF(K26="","Missing","Observed") -> Observed | N26: =LN(C26) -> 5.4889377 | O26: =IF($H26=1,1,0) -> 0 | P26: =IF($H26=2,1,0) -> 0 | Q26: =IF($H26=3,1,0) -> 0 | R26: =IF($L26="","",$L26-2018) -> 4
A27: BDI | B27: Burundi | C27: 392 | D27: 2023 | E27: 1033.0094 | F27: 2023 | G27: =LN(E27) -> 6.9402315 | H27: 1 | I27: Electoral autocracy | J27: 2023 | K27: 28.5 | L27: 2017 | M27: =IF(K27="","Missing","Observed") -> Observed | N27: =LN(C27) -> 5.9712618 | O27: =IF($H27=1,1,0) -> 1 | P27: =IF($H27=2,1,0) -> 0 | Q27: =IF($H27=3,1,0) -> 0 | R27: =IF($L27="","",$L27-2018) -> -1
A28: CPV | B28: Cabo Verde | C28: 40 | D28: 2023 | E28: 9228.4605 | F28: 2023 | G28: =LN(E28) -> 9.1300475 | H28: 2 | I28: Electoral democracy | J28: 2023 | K28: 55.8 | L28: 2018 | M28: =IF(K28="","Missing","Observed") -> Observed | N28: =LN(C28) -> 3.6888795 | O28: =IF($H28=1,1,0) -> 0 | P28: =IF($H28=2,1,0) -> 1 | Q28: =IF($H28=3,1,0) -> 0 | R28: =IF($L28="","",$L28-2018) -> 0
A29: KHM | B29: Cambodia | C29: 137 | D29: 2023 | E29: 6695.2919 | F29: 2023 | G29: =LN(E29) -> 8.8091599 | H29: 1 | I29: Electoral autocracy | J29: 2023 | K29: 61.9 | L29: 2022 | M29: =IF(K29="","Missing","Observed") -> Observed | N29: =LN(C29) -> 4.9199809 | O29: =IF($H29=1,1,0) -> 1 | P29: =IF($H29=2,1,0) -> 0 | Q29: =IF($H29=3,1,0) -> 0 | R29: =IF($L29="","",$L29-2018) -> 4
A30: CMR | B30: Cameroon | C30: 258 | D30: 2023 | E30: 4875.2512 | F30: 2023 | G30: =LN(E30) -> 8.4919269 | H30: 1 | I30: Electoral autocracy | J30: 2023 | K30: 19.3 | L30: 2018 | M30: =IF(K30="","Missing","Observed") -> Observed | N30: =LN(C30) -> 5.5529596 | O30: =IF($H30=1,1,0) -> 1 | P30: =IF($H30=2,1,0) -> 0 | Q30: =IF($H30=3,1,0) -> 0 | R30: =IF($L30="","",$L30-2018) -> 0
A31: CAN | B31: Canada | C31: 12 | D31: 2023 | E31: 58088.378 | F31: 2023 | G31: =LN(E31) -> 10.969721 | H31: 2 | I31: Electoral democracy | J31: 2023 | M31: =IF(K31="","Missing","Observed") -> Missing | N31: =LN(C31) -> 2.4849066 | O31: =IF($H31=1,1,0) -> 0 | P31: =IF($H31=2,1,0) -> 1 | Q31: =IF($H31=3,1,0) -> 0 | R31: =IF($L31="","",$L31-2018)
A32: CAF | B32: Central African Republic | C32: 692 | D32: 2023 | E32: 1132.6764 | F32: 2023 | G32: =LN(E32) -> 7.0323386 | H32: 1 | I32: Electoral autocracy | J32: 2023 | K32: 17.8 | L32: 2019 | M32: =IF(K32="","Missing","Observed") -> Observed | N32: =LN(C32) -> 6.539586 | O32: =IF($H32=1,1,0) -> 1 | P32: =IF($H32=2,1,0) -> 0 | Q32: =IF($H32=3,1,0) -> 0 | R32: =IF($L32="","",$L32-2018) -> 1
A33: TCD | B33: Chad | C33: 748 | D33: 2023 | E33: 2433.5333 | F33: 2023 | G33: =LN(E33) -> 7.7970995 | H33: 0 | I33: Closed autocracy | J33: 2023 | K33: 8.1 | L33: 2019 | M33: =IF(K33="","Missing","Observed") -> Observed | N33: =LN(C33) -> 6.617403 | O33: =IF($H33=1,1,0) -> 0 | P33: =IF($H33=2,1,0) -> 0 | Q33: =IF($H33=3,1,0) -> 0 | R33: =IF($L33="","",$L33-2018) -> 1
A34: CHL | B34: Chile | C34: 10 | D34: 2023 | E34: 29600.419 | F34: 2023 | G34: =LN(E34) -> 10.295544 | H34: 3 | I34: Liberal democracy | J34: 2023 | K34: 76.263525 | L34: 2016 | M34: =IF(K34="","Missing","Observed") -> Observed | N34: =LN(C34) -> 2.3025851 | O34: =IF($H34=1,1,0) -> 0 | P34: =IF($H34=2,1,0) -> 0 | Q34: =IF($H34=3,1,0) -> 1 | R34: =IF($L34="","",$L34-2018) -> -2
A35: CHN | B35: China | C35: 16 | D35: 2023 | E35: 22687.252 | F35: 2023 | G35: =LN(E35) -> 10.029558 | H35: 0 | I35: Closed autocracy | J35: 2023 | K35: 84.5 | L35: 2017 | M35: =IF(K35="","Missing","Observed") -> Observed | N35: =LN(C35) -> 2.7725887 | O35: =IF($H35=1,1,0) -> 0 | P35: =IF($H35=2,1,0) -> 0 | Q35: =IF($H35=3,1,0) -> 0 | R35: =IF($L35="","",$L35-2018) -> -1
A36: COL | B36: Colombia | C36: 59 | D36: 2023 | E36: 18406.624 | F36: 2023 | G36: =LN(E36) -> 9.8204659 | H36: 2 | I36: Electoral democracy | J36: 2023 | K36: 81 | L36: 2015 | M36: =IF(K36="","Missing","Observed") -> Observed | N36: =LN(C36) -> 4.0775374 | O36: =IF($H36=1,1,0) -> 0 | P36: =IF($H36=2,1,0) -> 1 | Q36: =IF($H36=3,1,0) -> 0 | R36: =IF($L36="","",$L36-2018) -> -3
A37: COM | B37: Comoros | C37: 179 | D37: 2023 | E37: 3508.1586 | F37: 2023 | G37: =LN(E37) -> 8.1628466 | H37: 1 | I37: Electoral autocracy | J37: 2023 | K37: 11.6 | L37: 2022 | M37: =IF(K37="","Missing","Observed") -> Observed | N37: =LN(C37) -> 5.1873858 | O37: =IF($H37=1,1,0) -> 1 | P37: =IF($H37=2,1,0) -> 0 | Q37: =IF($H37=3,1,0) -> 0 | R37: =IF($L37="","",$L37-2018) -> 4
A38: COD | B38: Congo, Dem. Rep. | C38: 427 | D38: 2023 | E38: 1559.3381 | F38: 2023 | G38: =LN(E38) -> 7.3520167 | H38: 1 | I38: Electoral autocracy | J38: 2023 | K38: 28.128686 | L38: 2018 | M38: =IF(K38="","Missing","Observed") -> Observed | N38: =LN(C38) -> 6.056784 | O38: =IF($H38=1,1,0) -> 1 | P38: =IF($H38=2,1,0) -> 0 | Q38: =IF($H38=3,1,0) -> 0 | R38: =IF($L38="","",$L38-2018) -> 0
A39: COG | B39: Congo, Rep. | C39: 241 | D39: 2023 | E39: 6172.2878 | F39: 2023 | G39: =LN(E39) -> 8.7278248 | H39: 1 | I39: Electoral autocracy | J39: 2023 | K39: 30.119493 | L39: 2015 | M39: =IF(K39="","Missing","Observed") -> Observed | N39: =LN(C39) -> 5.4847969 | O39: =IF($H39=1,1,0) -> 1 | P39: =IF($H39=2,1,0) -> 0 | Q39: =IF($H39=3,1,0) -> 0 | R39: =IF($L39="","",$L39-2018) -> -3
A40: CRI | B40: Costa Rica | C40: 24 | D40: 2023 | E40: 26378.541 | F40: 2023 | G40: =LN(E40) -> 10.180306 | H40: 3 | I40: Liberal democracy | J40: 2023 | K40: 70.9 | L40: 2018 | M40: =IF(K40="","Missing","Observed") -> Observed | N40: =LN(C40) -> 3.1780538 | O40: =IF($H40=1,1,0) -> 0 | P40: =IF($H40=2,1,0) -> 0 | Q40: =IF($H40=3,1,0) -> 1 | R40: =IF($L40="","",$L40-2018) -> 0
A41: CIV | B41: Cote d'Ivoire | C41: 359 | D41: 2023 | E41: 6520.8989 | F41: 2023 | G41: =LN(E41) -> 8.7827675 | H41: 1 | I41: Electoral autocracy | J41: 2023 | K41: 31.971157 | L41: 2022 | M41: =IF(K41="","Missing","Observed") -> Observed | N41: =LN(C41) -> 5.8833224 | O41: =IF($H41=1,1,0) -> 1 | P41: =IF($H41=2,1,0) -> 0 | Q41: =IF($H41=3,1,0) -> 0 | R41: =IF($L41="","",$L41-2018) -> 4
...

Sheet 描述统计
A1: 描述统计
A2: 所有指标直接引用“跨国底稿”；四分位数采用QUARTILE.INC，SD为样本标准差。
A4: 变量 | B4: n | C4: 均值 | D4: SD | E4: 中位数 | F4: IQR | G4: 最小值 | H4: 最大值 | I4: 数据列
A5: MMR per 100,000 live births | B5: =COUNT(跨国底稿!$C$5:$C$171) -> 167 | C5: =AVERAGE(跨国底稿!$C$5:$C$171) -> 116.94012 | D5: =stdev.s(跨国底稿!$C$5:$C$171) -> #NAME? | E5: =MEDIAN(跨国底稿!$C$5:$C$171) -> 41 | F5: =quartile.inc(跨国底稿!$C$5:$C$171,3)-quartile.inc(跨国底稿!$C$5:$C$171,1) -> #NAME? | G5: =MIN(跨国底稿!$C$5:$C$171) -> 1 | H5: =MAX(跨国底稿!$C$5:$C$171) -> 993 | I5: mmr
A6: log(MMR) | B6: =COUNT(跨国底稿!$N$5:$N$171) -> 167 | C6: =AVERAGE(跨国底稿!$N$5:$N$171) -> 3.6370804 | D6: =stdev.s(跨国底稿!$N$5:$N$171) -> #NAME? | E6: =MEDIAN(跨国底稿!$N$5:$N$171) -> 3.7135721 | F6: =quartile.inc(跨国底稿!$N$5:$N$171,3)-quartile.inc(跨国底稿!$N$5:$N$171,1) -> #NAME? | G6: =MIN(跨国底稿!$N$5:$N$171) -> 0 | H6: =MAX(跨国底稿!$N$5:$N$171) -> 6.9007307 | I6: log_mmr
A7: GDP per capita, PPP, constant 2021 intl $ | B7: =COUNT(跨国底稿!$E$5:$E$171) -> 167 | C7: =AVERAGE(跨国底稿!$E$5:$E$171) -> 25423.047 | D7: =stdev.s(跨国底稿!$E$5:$E$171) -> #NAME? | E7: =MEDIAN(跨国底稿!$E$5:$E$171) -> 15916.958 | F7: =quartile.inc(跨国底稿!$E$5:$E$171,3)-quartile.inc(跨国底稿!$E$5:$E$171,1) -> #NAME? | G7: =MIN(跨国底稿!$E$5:$E$171) -> 1033.0094 | H7: =MAX(跨国底稿!$E$5:$E$171) -> 130296.84 | I7: gdp_ppp_constant_2021
A8: log(GDP per capita) | B8: =COUNT(跨国底稿!$G$5:$G$171) -> 167 | C8: =AVERAGE(跨国底稿!$G$5:$G$171) -> 9.5713219 | D8: =stdev.s(跨国底稿!$G$5:$G$171) -> #NAME? | E8: =MEDIAN(跨国底稿!$G$5:$G$171) -> 9.6751404 | F8: =quartile.inc(跨国底稿!$G$5:$G$171,3)-quartile.inc(跨国底稿!$G$5:$G$171,1) -> #NAME? | G8: =MIN(跨国底稿!$G$5:$G$171) -> 6.9402315 | H8: =MAX(跨国底稿!$G$5:$G$171) -> 11.777571 | I8: log_gdp
A9: Political regime code (0-3) | B9: =COUNT(跨国底稿!$H$5:$H$171) -> 166 | C9: =AVERAGE(跨国底稿!$H$5:$H$171) -> 1.5662651 | D9: =stdev.s(跨国底稿!$H$5:$H$171) -> #NAME? | E9: =MEDIAN(跨国底稿!$H$5:$H$171) -> 2 | F9: =quartile.inc(跨国底稿!$H$5:$H$171,3)-quartile.inc(跨国底稿!$H$5:$H$171,1) -> #NAME? | G9: =MIN(跨国底稿!$H$5:$H$171) -> 0 | H9: =MAX(跨国底稿!$H$5:$H$171) -> 3 | I9: regime_code
A10: Contraceptive prevalence, any method (%) | B10: =COUNT(跨国底稿!$K$5:$K$171) -> 139 | C10: =AVERAGE(跨国底稿!$K$5:$K$171) -> 49.895563 | D10: =stdev.s(跨国底稿!$K$5:$K$171) -> #NAME? | E10: =MEDIAN(跨国底稿!$K$5:$K$171) -> 54.6 | F10: =quartile.inc(跨国底稿!$K$5:$K$171,3)-quartile.inc(跨国底稿!$K$5:$K$171,1) -> #NAME? | G10: =MIN(跨国底稿!$K$5:$K$171) -> 6.9 | H10: =MAX(跨国底稿!$K$5:$K$171) -> 85.47486 | I10: cpr
A11: CPR observation year | B11: =COUNT(跨国底稿!$L$5:$L$171) -> 139 | C11: =AVERAGE(跨国底稿!$L$5:$L$171) -> 2017.741 | D11: =stdev.s(跨国底稿!$L$5:$L$171) -> #NAME? | E11: =MEDIAN(跨国底稿!$L$5:$L$171) -> 2018 | F11: =quartile.inc(跨国底稿!$L$5:$L$171,3)-quartile.inc(跨国底稿!$L$5:$L$171,1) -> #NAME? | G11: =MIN(跨国底稿!$L$5:$L$171) -> 2010 | H11: =MAX(跨国底稿!$L$5:$L$171) -> 2023 | I11: cpr_year

Sheet 缺失分析
A1: CPR缺失分析
A2: 按政治体制类别统计；PSE因统一政治体制缺失，不纳入分组率。自由民主组缺失集中是主要选择偏倚风险。
A4: 政治体制代码 | B4: 政治体制类别 | C4: 总数 | D4: CPR观测数 | E4: CPR缺失数 | F4: 缺失率
A5: 0 | B5: Closed autocracy | C5: =COUNTIF(跨国底稿!$H$5:$H$171,A5) -> 27 | D5: =COUNTIFS(跨国底稿!$H$5:$H$171,A5,跨国底稿!$M$5:$M$171,"Observed") -> 24 | E5: =COUNTIFS(跨国底稿!$H$5:$H$171,A5,跨国底稿!$M$5:$M$171,"Missing") -> 3 | F5: =IFERROR(E5/C5,"") -> 0.11111111
A6: 1 | B6: Electoral autocracy | C6: =COUNTIF(跨国底稿!$H$5:$H$171,A6) -> 51 | D6: =COUNTIFS(跨国底稿!$H$5:$H$171,A6,跨国底稿!$M$5:$M$171,"Observed") -> 47 | E6: =COUNTIFS(跨国底稿!$H$5:$H$171,A6,跨国底稿!$M$5:$M$171,"Missing") -> 4 | F6: =IFERROR(E6/C6,"") -> 0.078431373
A7: 2 | B7: Electoral democracy | C7: =COUNTIF(跨国底稿!$H$5:$H$171,A7) -> 55 | D7: =COUNTIFS(跨国底稿!$H$5:$H$171,A7,跨国底稿!$M$5:$M$171,"Observed") -> 45 | E7: =COUNTIFS(跨国底稿!$H$5:$H$171,A7,跨国底稿!$M$5:$M$171,"Missing") -> 10 | F7: =IFERROR(E7/C7,"") -> 0.18181818
A8: 3 | B8: Liberal democracy | C8: =COUNTIF(跨国底稿!$H$5:$H$171,A8) -> 33 | D8: =COUNTIFS(跨国底稿!$H$5:$H$171,A8,跨国底稿!$M$5:$M$171,"Observed") -> 22 | E8: =COUNTIFS(跨国底稿!$H$5:$H$171,A8,跨国底稿!$M$5:$M$171,"Missing") -> 11 | F8: =IFERROR(E8/C8,"") -> 0.33333333
A11: CPR缺失国家清单
A12: ISO3 | B12: 国家 | C12: 政治体制代码 | D12: 政治体制类别 | E12: 风险说明
A13: BHR | B13: Bahrain | C13: 0 | D13: Closed autocracy | E13: 缺失可能非随机
A14: BGR | B14: Bulgaria | C14: 2 | D14: Electoral democracy | E14: 缺失可能非随机
A15: CAN | B15: Canada | C15: 2 | D15: Electoral democracy | E15: 缺失可能非随机
A16: HRV | B16: Croatia | C16: 2 | D16: Electoral democracy | E16: 缺失可能非随机
A17: CYP | B17: Cyprus | C17: 3 | D17: Liberal democracy | E17: 自由民主组集中缺失；可能影响CPR推断
A18: CZE | B18: Czechia | C18: 3 | D18: Liberal democracy | E18: 自由民主组集中缺失；可能影响CPR推断
A19: DNK | B19: Denmark | C19: 3 | D19: Liberal democracy | E19: 自由民主组集中缺失；可能影响CPR推断
A20: GRC | B20: Greece | C20: 2 | D20: Electoral democracy | E20: 缺失可能非随机
A21: HUN | B21: Hungary | C21: 1 | D21: Electoral autocracy | E21: 缺失可能非随机
A22: ISL | B22: Iceland | C22: 3 | D22: Liberal democracy | E22: 自由民主组集中缺失；可能影响CPR推断
A23: ISR | B23: Israel | C23: 2 | D23: Electoral democracy | E23: 缺失可能非随机
A24: KWT | B24: Kuwait | C24: 1 | D24: Electoral autocracy | E24: 缺失可能非随机
... A40: URY | B40: Uruguay | C40: 3 | D40: Liberal democracy | E40: 自由民主组集中缺失；可能影响CPR推断

Sheet 相关系数
A1: 双变量相关系数
A2: Pearson r；每一行都显示自己的有效样本量，不将MMR与CPR统一标为n=167。
A4: 变量X | B4: 变量Y | C4: n | D4: Pearson r | E4: 解释
A5: 政治体制代码 | B5: log(MMR) | C5: 166 | D5: =CORREL(跨国底稿!$H$5:$H$171,跨国底稿!$N$5:$N$171) -> -0.44139698 | E5: 双变量梯度；不作因果解释
A6: 政治体制代码 | B6: MMR | C6: 166 | D6: =CORREL(跨国底稿!$H$5:$H$171,跨国底稿!$C$5:$C$171) -> -0.36795918 | E6: 双变量梯度；不作因果解释
A7: 政治体制代码 | B7: CPR | C7: 138 | D7: =CORREL(跨国底稿!$H$5:$H$171,跨国底稿!$K$5:$K$171) -> 0.44571859 | E7: 双变量正向梯度；CPR缺失需注意
A8: logGDP | B8: log(MMR) | C8: 167 | D8: =CORREL(跨国底稿!$G$5:$G$171,跨国底稿!$N$5:$N$171) -> -0.84973307 | E8: 背景相关
A9: logGDP | B9: MMR | C9: 167 | D9: =CORREL(跨国底稿!$G$5:$G$171,跨国底稿!$C$5:$C$171) -> -0.71599115 | E9: 背景相关
A10: logGDP | B10: CPR | C10: 139 | D10: =CORREL(跨国底稿!$G$5:$G$171,跨国底稿!$K$5:$K$171) -> 0.57520484 | E10: 背景相关
A11: 政治体制代码 | B11: logGDP | C11: 166 | D11: =CORREL(跨国底稿!$H$5:$H$171,跨国底稿!$G$5:$G$171) -> 0.4886845 | E11: 收入可能混杂体制与健康关联

Sheet 模型结果
A1: 主要模型结果
A2: HC3为主要推断；经典OLS并列。β是政治体制每提高一个类别的变化，前提是0–3等距趋势成立。
A4: 模型 | B4: 政治体制项 | C4: n | D4: df | E4: β | F4: 经典SE | G4: 经典p | H4: HC3 SE | I4: HC3 p | J4: HC3 95%CI下限 | K4: HC3 95%CI上限 | L4: R² | M4: 调整R²
A5: M1 Primary: log(MMR), ordinal regime | B5: regime_code | C5: 166 | D5: 163 | E5: -0.053071686 | F5: 0.07920164 | G5: 0.50375297 | H5: 0.075181127 | I5: 0.48124704 | J5: -0.20152619 | K5: 0.095382819 | L5: 0.73116932 | M5: 0.72787079
A6: M3 Primary: CPR 2010-2023 latest | B6: regime_code | C6: 138 | D6: 135 | E6: 4.8272991 | F6: 1.6771452 | G6: 0.0046502135 | H6: 1.9817133 | I6: 0.016157782 | J6: 0.90808006 | K6: 8.7465182 | L6: 0.37260227 | M6: 0.36330749
A8: 完整参数表（包括截距和logGDP）
A9: 模型 | B9: 模型项 | C9: n | D9: df | E9: β | F9: 经典SE | G9: 经典p | H9: HC3 SE | I9: HC3 p | J9: HC3 95%CI下限 | K9: HC3 95%CI上限 | L9: R² | M9: 调整R²
A10: M1 Primary: log(MMR), ordinal regime | B10: Intercept | C10: 166 | D10: 163 | E10: 15.25002 | F10: 0.59240811 | G10: 2.6046446e-59 | H10: 0.52858716 | I10: 6.1894305e-66 | J10: 14.206259 | K10: 16.293781 | L10: 0.73116932 | M10: 0.72787079
A11: M1 Primary: log(MMR), ordinal regime | B11: regime_code | C11: 166 | D11: 163 | E11: -0.053071686 | F11: 0.07920164 | G11: 0.50375297 | H11: 0.075181127 | I11: 0.48124704 | J11: -0.20152619 | K11: 0.095382819 | L11: 0.73116932 | M11: 0.72787079
A12: M1 Primary: log(MMR), ordinal regime | B12: log_gdp | C12: 166 | D12: 163 | E12: -1.2033593 | F12: 0.066730076 | G12: 1.1345863e-40 | H12: 0.06114315 | I12: 6.3394791e-45 | J12: -1.324094 | K12: -1.0826245 | L12: 0.73116932 | M12: 0.72787079
A13: M3 Primary: CPR 2010-2023 latest | B13: Intercept | C13: 138 | D13: 135 | E13: -39.68471 | F13: 12.579757 | G13: 0.0019812816 | H13: 12.833748 | I13: 0.0024143392 | J13: -65.065914 | K13: -14.303507 | L13: 0.37260227 | M13: 0.36330749
A14: M3 Primary: CPR 2010-2023 latest | B14: regime_code | C14: 138 | D14: 135 | E14: 4.8272991 | F14: 1.6771452 | G14: 0.0046502135 | H14: 1.9817133 | I14: 0.016157782 | J14: 0.90808006 | K14: 8.7465182 | L14: 0.37260227 | M14: 0.36330749
A15: M3 Primary: CPR 2010-2023 latest | B15: log_gdp | C15: 138 | D15: 135 | E15: 8.8202767 | F15: 1.441752 | G15: 9.6295034e-09 | H15: 1.5844364 | I15: 1.3477843e-07 | J15: 5.686749 | K15: 11.953804 | L15: 0.37260227 | M15: 0.36330749

Sheet 稳健性分析
A1: 稳健性分析
A2: 本表报告全部设定的敏感性规格，用于比较估计方向、大小和不确定性。
A4: 模型 | B4: 政治体制项 | C4: n | D4: df | E4: β | F4: 经典SE | G4: 经典p | H4: HC3 SE | I4: HC3 p | J4: HC3 95%CI下限 | K4: HC3 95%CI上限 | L4: R² | M4: 调整R²
A5: M2 Sensitivity: raw MMR, ordinal regime | B5: regime_code | C5: 166 | D5: 163 | E5: -3.4873778 | F5: 10.618782 | G5: 0.74301867 | H5: 9.2454878 | I5: 0.70651724 | J5: -21.743746 | K5: 14.76899 | L5: 0.52037972 | M5: 0.51449481
A6: M3 Primary: CPR 2010-2023 latest | B6: regime_code | C6: 138 | D6: 135 | E6: 4.8272991 | F6: 1.6771452 | G6: 0.0046502135 | H6: 1.9817133 | I6: 0.016157782 | J6: 0.90808006 | K6: 8.7465182 | L6: 0.37260227 | M6: 0.36330749
A7: M4 CPR + observation year | B7: regime_code | C7: 138 | D7: 134 | E7: 4.8004654 | F7: 1.6867621 | G7: 0.0051243514 | H7: 2.0299201 | I7: 0.019471732 | J7: 0.78563721 | K7: 8.8152936 | L7: 0.37287036 | M7: 0.35883014
A8: M5 CPR restricted to 2015-2023 | B8: regime_code | C8: 109 | D8: 106 | E8: 3.2652646 | F8: 2.0152672 | G8: 0.10814689 | H8: 2.3616113 | I8: 0.16968048 | J8: -1.4168596 | K8: 7.9473888 | L8: 0.34203998 | M8: 0.32962564
A9: M6 log(MMR), regime categorical | B9: regime_1 | C9: 166 | D9: 161 | E9: 0.10256134 | F9: 0.20953179 | G9: 0.62516909 | H9: 0.21353557 | I9: 0.63166535 | J9: -0.31913043 | K9: 0.52425311 | L9: 0.73224448 | M9: 0.72559217
A10: M6 log(MMR), regime categorical | B10: regime_2 | C10: 166 | D10: 161 | E10: -0.045545154 | F10: 0.20917578 | G10: 0.82791031 | H10: 0.20352328 | I10: 0.82320948 | J10: -0.44746458 | K10: 0.35637427 | L10: 0.73224448 | M10: 0.72559217
A11: M6 log(MMR), regime categorical | B11: regime_3 | C11: 166 | D11: 161 | E11: -0.11901416 | F11: 0.25724684 | G11: 0.64424297 | H11: 0.24085434 | I11: 0.62188551 | J11: -0.59465527 | K11: 0.35662695 | L11: 0.73224448 | M11: 0.72559217
A12: M7 CPR, regime categorical | B12: regime_1 | C12: 138 | D12: 133 | E12: 3.3902429 | F12: 4.1949208 | G12: 0.42043128 | H12: 4.9425136 | I12: 0.4939481 | J12: -6.3858576 | K12: 13.166343 | L12: 0.37574634 | M12: 0.35697179
A13: M7 CPR, regime categorical | B13: regime_2 | C13: 138 | D13: 133 | E13: 10.613061 | F13: 4.2546074 | G13: 0.013839066 | H13: 5.1246886 | I13: 0.040295335 | J13: 0.47662545 | K13: 20.749497 | L13: 0.37574634 | M13: 0.35697179
A14: M7 CPR, regime categorical | B14: regime_3 | C14: 138 | D14: 133 | E14: 12.477392 | F14: 5.6393267 | G14: 0.028633295 | H14: 6.3825122 | I14: 0.052688121 | J14: -0.14696996 | K14: 25.101754 | L14: 0.37574634 | M14: 0.35697179

Sheet 模型输出与HC3结果
A1: OLS与HC3完整计算记录
A2: 根据逐国底稿在外部统计程序中计算；p 值与 95% 置信区间均使用有限自由度 t 分布。下方给出计算公式与完整输出。
A4: 模型 | B4: 因变量 | C4: 预测变量 | D4: 项 | E4: n | F4: k | G4: df | H4: β | I4: 经典SE | J4: 经典t | K4: 经典p | L4: 经典CI下 | M4: 经典CI上 | N4: HC3 SE | O4: HC3 t | P4: HC3 p | Q4: HC3 CI下 | R4: HC3 CI上 | S4: R² | T4: 调整R²
A5: M1 Primary: log(MMR), ordinal regime | B5: log_mmr | C5: regime_code + log_gdp | D5: Intercept | E5: 166 | F5: 3 | G5: 163 | H5: 15.25002 | I5: 0.59240811 | J5: 25.742423 | K5: 2.6046446e-59 | L5: 14.080236 | M5: 16.419804 | N5: 0.52858716 | O5: 28.850531 | P5: 6.1894305e-66 | Q5: 14.206259 | R5: 16.293781 | S5: 0.73116932 | T5: 0.72787079
A6: M1 Primary: log(MMR), ordinal regime | B6: log_mmr | C6: regime_code + log_gdp | D6: regime_code | E6: 166 | F6: 3 | G6: 163 | H6: -0.053071686 | I6: 0.07920164 | J6: -0.67008317 | K6: 0.50375297 | L6: -0.2094652 | M6: 0.10332182 | N6: 0.075181127 | O6: -0.70591767 | P6: 0.48124704 | Q6: -0.20152619 | R6: 0.095382819 | S6: 0.73116932 | T6: 0.72787079
A7: M1 Primary: log(MMR), ordinal regime | B7: log_mmr | C7: regime_code + log_gdp | D7: log_gdp | E7: 166 | F7: 3 | G7: 163 | H7: -1.2033593 | I7: 0.066730076 | J7: -18.033237 | K7: 1.1345863e-40 | L7: -1.3351261 | M7: -1.0715924 | N7: 0.06114315 | O7: -19.681015 | P7: 6.3394791e-45 | Q7: -1.324094 | R7: -1.0826245 | S7: 0.73116932 | T7: 0.72787079
A8: M2 Sensitivity: raw MMR, ordinal regime | B8: mmr | C8: regime_code + log_gdp | D8: Intercept | E8: 166 | F8: 3 | G8: 163 | H8: 1103.0877 | I8: 79.425786 | J8: 13.888282 | K8: 1.9391064e-29 | L8: 946.25161 | M8: 1259.9238 | N8: 98.594433 | O8: 11.188134 | P8: 6.3719034e-22 | Q8: 908.40073 | R8: 1297.7747 | S8: 0.52037972 | T8: 0.51449481
A9: M2 Sensitivity: raw MMR, ordinal regime | B9: mmr | C9: regime_code + log_gdp | D9: regime_code | E9: 166 | F9: 3 | G9: 163 | H9: -3.4873778 | I9: 10.618782 | J9: -0.32841599 | K9: 0.74301867 | L9: -24.455486 | M9: 17.480731 | N9: 9.2454878 | O9: -0.37719781 | P9: 0.70651724 | Q9: -21.743746 | R9: 14.76899 | S9: 0.52037972 | T9: 0.51449481
A10: M2 Sensitivity: raw MMR, ordinal regime | B10: mmr | C10: regime_code + log_gdp | D10: log_gdp | E10: 166 | F10: 3 | G10: 163 | H10: -102.33625 | I10: 8.946685 | J10: -11.438455 | K10: 1.2885676e-22 | L10: -120.0026 | M10: -84.66991 | N10: 10.15821 | O10: -10.074241 | P10: 7.3440321e-19 | Q10: -122.39491 | R10: -82.277602 | S10: 0.52037972 | T10: 0.51449481
A11: M3 Primary: CPR 2010-2023 latest | B11: cpr | C11: regime_code + log_gdp | D11: Intercept | E11: 138 | F11: 3 | G11: 135 | H11: -39.68471 | I11: 12.579757 | J11: -3.1546485 | K11: 0.0019812816 | L11: -64.563598 | M11: -14.805823 | N11: 12.833748 | O11: -3.0922153 | P11: 0.0024143392 | Q11: -65.065914 | R11: -14.303507 | S11: 0.37260227 | T11: 0.36330749
A12: M3 Primary: CPR 2010-2023 latest | B12: cpr | C12: regime_code + log_gdp | D12: regime_code | E12: 138 | F12: 3 | G12: 135 | H12: 4.8272991 | I12: 1.6771452 | J12: 2.8782833 | K12: 0.0046502135 | L12: 1.5104219 | M12: 8.1441763 | N12: 1.9817133 | O12: 2.4359221 | P12: 0.016157782 | Q12: 0.90808006 | R12: 8.7465182 | S12: 0.37260227 | T12: 0.36330749
A13: M3 Primary: CPR 2010-2023 latest | B13: cpr | C13: regime_code + log_gdp | D13: log_gdp | E13: 138 | F13: 3 | G13: 135 | H13: 8.8202767 | I13: 1.441752 | J13: 6.1177491 | K13: 9.6295034e-09 | L13: 5.968935 | M13: 11.671618 | N13: 1.5844364 | O13: 5.5668227 | P13: 1.3477843e-07 | Q13: 5.686749 | R13: 11.953804 | S13: 0.37260227 | T13: 0.36330749
A14: M4 CPR + observation year | B14: cpr | C14: regime_code + log_gdp + cpr_year_centered_2018 | D14: Intercept | E14: 138 | F14: 4 | G14: 134 | H14: -38.760326 | I14: 13.201521 | J14: -2.9360501 | K14: 0.0039135381 | L14: -64.870634 | M14: -12.650018 | N14: 13.51527 | O14: -2.8678913 | P14: 0.0048016233 | Q14: -65.491176 | R14: -12.029476 | S14: 0.37287036 | T14: 0.35883014
A15: M4 CPR + observation year | B15: cpr | C15: regime_code + log_gdp + cpr_year_centered_2018 | D15: regime_code | E15: 138 | F15: 4 | G15: 134 | H15: 4.8004654 | I15: 1.6867621 | J15: 2.8459647 | K15: 0.0051243514 | L15: 1.4643438 | M15: 8.136587 | N15: 2.0299201 | O15: 2.3648544 | P15: 0.019471732 | Q15: 0.78563721 | R15: 8.8152936 | S15: 0.37287036 | T15: 0.35883014
A16: M4 CPR + observation year | B16: cpr | C16: regime_code + log_gdp + cpr_year_centered_2018 | D16: log_gdp | E16: 138 | F16: 4 | G16: 134 | H16: 8.7225903 | I16: 1.5032813 | J16: 5.8023674 | K16: 4.4899856e-08 | L16: 5.7493619 | M16: 11.695819 | N16: 1.6313494 | O16: 5.3468561 | P16: 3.7505101e-07 | Q16: 5.4960656 | R16: 11.949115 | S16: 0.37287036 | T16: 0.35883014
... A30: M7 CPR, regime categorical | B30: cpr | C30: regime_1 + regime_2 + regime_3 + log_gdp | D30: log_gdp | E30: 138 | F30: 5 | G30: 133 | H30: 9.0047824 | I30: 1.5595805 | J30: 5.773849 | K30: 5.2063253e-08 | L30: 5.9199926 | M30: 12.089572 | N30: 1.6966468 | O30: 5.3073996 | P30: 4.5279221e-07 | Q30: 5.6488808 | R30: 12.360684 | S30: 0.37574634 | T30: 0.35697179
A33: HC3: (X'X)^−1 X' diag[eᵢ²/(1−hᵢᵢ)²] X (X'X)^−1. Two-sided p = 2·Pr(Tdf ≥ |t|), df = n−k. 95% CI = β ± t0.975,df·SEHC3.

Sheet 隐私证据矩阵
A1: FemTech隐私证据矩阵
A2: 不同样本、方法和终点不合并为单一比例；每条记录保留各自的分子、分母与终点。
A4: 来源/案例 | B4: 研究对象 | C4: 平台 | D4: 地区 | E4: 样本量 | F4: 分子 | G4: 分母 | H4: 实际终点 | I4: 研究方法 | J4: 证据类型 | K4: 可比性限制 | L4: 原始链接 | M4: 后续整改/状态
A5: Mozilla *Privacy Not Included* review | B5: 20 period/pregnancy apps and 5 wearable devices | C5: Mobile apps and connected wearables | D5: Products available to US consumers | E5: 25 | F5: 18 | G5: 25 | H5: Products assigned Mozilla's *Privacy Not Included* warning | I5: Desk-based product privacy/security review against Mozilla criteria | J5: Independent civil-society review | K5: Includes 5 devices; warning criteria are not equivalent to observed third-party transmission. | L5: https://www.mozillafoundation.org/en/blog/in-post-roe-v-wade-era-mozilla-labels-18-of-25-popular-period-and-pregnancy-tracking-tech-with-privacy-not-included-warning/ | M5: Product-level practices may have changed after 2022; the cited page is a contemporaneous review.
A6: Grundy et al., BMJ (2019) | B6: 24 medicines-related Android apps | C6: Android | D6: Apps available in four countries | E6: 24 | F6: 19 | G6: 24 | H6: Apps sharing user data outside the app ecosystem | I6: Traffic analysis plus network mapping of data recipients | J6: Peer-reviewed empirical study | K6: Not a reproductive-health-app sample; endpoint differs from Mozilla's warning label. | L6: https://www.bmj.com/content/364/bmj.l920 | M6: No product-level remediation assessment in this workpaper.
A7: FTC final order: Flo Health (2021) | B7: Flo period and ovulation tracking app | C7: Mobile app | D7: United States enforcement | H7: Alleged disclosure of sensitive health data to analytics/marketing firms contrary to privacy promises | I7: Regulatory investigation and consent order | J7: Individual enforcement case | K7: A case, not a prevalence estimate; cannot be pooled with audit proportions. | L7: https://www.ftc.gov/news-events/news/press-releases/2021/06/ftc-finalizes-order-flo-health-fertility-tracking-app-shared-sensitive-health-data-facebook-google | M7: Flo states that an independent privacy review required by the order was completed in March 2022.
A8: FTC proposed order: Premom/Easy Healthcare (2023) | B8: Premom ovulation tracking app | C8: Mobile app | D8: United States enforcement | H8: Alleged sharing of sensitive health data; proposed order and US$100,000 civil penalty | I8: Regulatory investigation and proposed consent order | J8: Individual enforcement case | K8: A case, not a prevalence estimate; cannot be pooled with audit proportions. | L8: https://www.ftc.gov/news-events/news/press-releases/2023/05/ovulation-tracking-app-premom-will-be-barred-sharing-health-data-advertising-under-proposed-ftc | M8: The workpaper does not independently verify later compliance.

Sheet 一致性检查
A1: 工作簿一致性检查
A2: 关键样本量、编码、缺失和公式错误检查；PASS表示当前工作簿内部一致。
A4: 检查项目 | B4: 状态 | C4: 含义
A5: 逐国底稿行数=167 | B5: =IF(COUNTA(跨国底稿!$A$5:$A$171)=167,"PASS","FAIL") -> PASS | C5: 维持167国分析总体
A6: MMR有效n=167 | B6: =IF(COUNT(跨国底稿!$C$5:$C$171)=167,"PASS","FAIL") -> PASS | C6: MMR数值完整
A7: 政治体制有效n=166 | B7: =IF(COUNT(跨国底稿!$H$5:$H$171)=166,"PASS","FAIL") -> PASS | C7: PSE统一值缺失
A8: 政治体制无范围外值 | B8: =IF(COUNTIF(跨国底稿!$H$5:$H$171,"<0")+COUNTIF(跨国底稿!$H$5:$H$171,">3")=0,"PASS","FAIL") -> PASS | C8: 仅允许0/1/2/3或空白
A9: CPR有效n=139 | B9: =IF(COUNT(跨国底稿!$K$5:$K$171)=139,"PASS","FAIL") -> PASS | C9: 逐国CPR原始覆盖
A10: CPR模型n=138 | B10: =IF(COUNTIFS(跨国底稿!$K$5:$K$171,"<>",跨国底稿!$H$5:$H$171,"<>")=138,"PASS","FAIL") -> PASS | C10: PSE因政治体制缺失再少1国
A11: CPR缺失=28 | B11: =IF(COUNTIF(跨国底稿!$M$5:$M$171,"Missing")=28,"PASS","FAIL") -> PASS | C11: 与刷新后的逐国表一致
A12: CPR年份2010-2023 | B12: =IF(AND(MIN(跨国底稿!$L$5:$L$171)>=2010,MAX(跨国底稿!$L$5:$L$171)<=2023),"PASS","FAIL") -> PASS | C12: 主样本年份规则
A13: 无公式错误 | B13: =IF(SUMPRODUCT(--ISERROR(跨国底稿!$G$5:$G$171))+SUMPRODUCT(--ISERROR(跨国底稿!$M$5:$N$171))=0,"PASS","FAIL") -> PASS | C13: 关键公式列

Sheet 分析复现说明
A1: 分析复现说明
A2: 「模型结果」「稳健性分析」「模型输出与HC3结果」三表的数值由外部统计程序根据「跨国底稿」计算后录入，不随逐国数据自动重算。下列代码可在任意装有 NumPy 的 Python 3 环境中完整复现三表全部数值。
A4: # Requires: Python 3, NumPy, and openpyxl. No dedicated statistical package is used.
A5: # p values and 95% CIs use the t distribution with finite degrees of freedom (not a normal approximation).
A6: # 输入：本工作簿「跨国底稿」工作表，第 5-171 行，列 C=MMR、E=原始GDP、H=政治体制代码、K=CPR、L=CPR年份。
A7: # G 列 logGDP = LN(E)，N 列 log(MMR) = LN(C)，O/Q/R 列为派生虚拟变量（均为工作簿内公式）。
A8: # 输出：与「模型结果」「稳健性分析」「模型输出与HC3结果」三表逐位一致（误差量级 1e-10 以下）。
A9: import numpy as np, openpyxl
A10: from math import lgamma, exp, log
A11: # 自动定位同目录下的数据表工作簿（无需改名即可运行）
A12: import glob as _glob, os as _os
A13: _cand = _glob.glob(_os.path.join(_os.path.dirname(_os.path.abspath(__file__)) or ".", "*数据表*.xlsx"))
... A82: ols(cpr, [e1, e2, e3, c_lg], ["Intercept", "regime_1", "regime_2", "regime_3", "logGDP"]) # M7
